File: Example Data File - Instron.csv
Time (sec),S:Load (lbs),S:Position (in),Ch:Position (mm),Ch:Load (lbs),Ch:Stress (kPa),Ch:Strain (lbs),Cycles (),Time_P&V (),S:Load_P&V (),S:Position_P&V (),Ch:Position_P&V (),Ch:Load_P&V (),Ch:Stress_P&V (),Ch:Strain_P&V (),Cycles_P&V ()
0.12,-0.007214,0.000025,0.000625,-0.007214,-1.634752,0.000125,0,,,,,,,,
0.48,0.103804,0.000268,0.006797,0.103804,23.522266,0.001359,0,,,,,,,,
0.84,0.184763,0.000468,0.011875,0.184763,41.867821,0.002375,0,,,,,,,,
1.2,0.400386,0.000719,0.018256,0.400386,90.728745,0.003651,0,,,,,,,,
1.56,0.721015,0.000959,0.02435,0.721015,163.384384,0.00487,0,,,,,,,,
1.92,0.943452,0.001204,0.030574,0.943452,213.789246,0.006115,0,,,,,,,,
2.28,1.135429,0.001426,0.036225,1.135429,257.291809,0.007245,0,,,,,,,,
2.64,1.442832,0.001665,0.042293,1.442832,326.950409,0.008459,0,,,,,,,,
3,1.831194,0.001912,0.048569,1.831194,414.954559,0.009714,0,,,,,,,,
3.36,2.155431,0.002147,0.054533,2.155431,488.427582,0.010907,0,,,,,,,,
3.72,2.503715,0.002368,0.060158,2.503715,567.349792,0.012032,0,,,,,,,,
4.08,2.866426,0.002586,0.065679,2.866426,649.541504,0.013136,0,,,,,,,,
4.44,3.312502,0.002842,0.072189,3.312502,750.623657,0.014438,0,,,,,,,,
4.8,3.686035,0.003087,0.078414,3.686035,835.267456,0.015683,0,,,,,,,,
5.16,4.038727,0.003314,0.084169,4.038727,915.18866,0.016834,0,,,,,,,,
5.52,4.441919,0.003545,0.090054,4.441919,1006.553162,0.018011,0,,,,,,,,
5.88,4.792607,0.0038,0.096513,4.792607,1086.020264,0.019303,0,,,,,,,,
6.24,5.093197,0.004037,0.102529,5.093197,1154.134888,0.020506,0,,,,,,,,
6.6,5.465929,0.004281,0.108727,5.465929,1238.597168,0.021745,0,,,,,,,,
6.960001,5.679548,0.004494,0.114144,5.679548,1287.004028,0.022829,0,,,,,,,,
7.32,5.897175,0.004726,0.120029,5.897175,1336.31897,0.024006,0,,,,,,,,
7.68,6.144461,0.004967,0.126149,6.144461,1392.354614,0.02523,0,,,,,,,,
8.04,6.389742,0.005215,0.132451,6.389742,1447.936279,0.02649,0,,,,,,,,
8.400001,6.567291,0.005434,0.138025,6.567291,1488.169312,0.027605,0,,,,,,,,
8.76,6.768486,0.005671,0.14404,6.768486,1533.76062,0.028808,0,,,,,,,,
9.120001,7.039818,0.005929,0.150603,7.039818,1595.245483,0.030121,0,,,,,,,,
9.48,7.272676,0.006156,0.156358,7.272676,1648.011841,0.031272,0,,,,,,,,
9.84,7.534389,0.006392,0.162348,7.534389,1707.316895,0.03247,0,,,,,,,,
10.200001,7.799309,0.006614,0.167999,7.799309,1767.348633,0.0336,0,,,,,,,,
10.56,8.145989,0.006863,0.174328,8.145989,1845.907471,0.034866,0,,,,,,,,
10.92,8.376842,0.007084,0.179927,8.376842,1898.219482,0.035985,0,,,,,,,,
11.280001,8.693865,0.007328,0.186125,8.693865,1970.057861,0.037225,0,,,,,,,,
11.64,9.002069,0.00755,0.191776,9.002069,2039.898071,0.038355,0,,,,,,,,
12.000001,9.275807,0.007808,0.198313,9.275807,2101.927979,0.039663,0,,,,,,,,
12.360001,9.524695,0.008035,0.204094,9.524695,2158.32666,0.040819,0,,,,,,,,
12.72,9.846929,0.008292,0.210605,9.846929,2231.345947,0.042121,0,,,,,,,,
13.080001,10.239699,0.008523,0.21649,10.239699,2320.348877,0.043298,0,,,,,,,,
13.440001,10.547904,0.008729,0.221725,10.547904,2390.189209,0.044345,0,,,,,,,,
13.8,11.082554,0.009001,0.228626,11.082554,2511.342529,0.045725,0,,,,,,,,
14.160001,11.404386,0.009219,0.234173,11.404386,2584.270508,0.046835,0,,,,,,,,
14.52,11.794751,0.009451,0.240058,11.794751,2672.728516,0.048012,0,,,,,,,,
14.880001,12.210768,0.009682,0.245918,12.210768,2766.999512,0.049184,0,,,,,,,,
15.240001,12.668867,0.009924,0.252064,12.668867,2870.806152,0.050413,0,,,,,,,,
15.6,13.114943,0.010178,0.258523,13.114943,2971.888428,0.051705,0,,,,,,,,
15.960001,13.494888,0.010414,0.264512,13.494888,3057.985352,0.052902,0,,,,,,,,
16.320002,13.877239,0.010628,0.269955,13.877239,3144.627197,0.053991,0,,,,,,,,
16.68,14.290851,0.010874,0.276205,14.290851,3238.352783,0.055241,0,,,,,,,,
17.040001,14.687229,0.011108,0.282143,14.687229,3328.173584,0.056429,0,,,,,,,,
17.400002,15.12569,0.011346,0.288185,15.12569,3427.530029,0.057637,0,,,,,,,,
17.76,15.49241,0.011564,0.293732,15.49241,3510.630127,0.058746,0,,,,,,,,
18.120001,15.920049,0.011808,0.29993,15.920049,3607.534424,0.059986,0,,,,,,,,
18.480001,16.4042,0.012059,0.30631,16.4042,3717.244629,0.061262,0,,,,,,,,
18.84,16.808594,0.012286,0.312066,16.808594,3808.881592,0.062413,0,,,,,,,,
19.200001,17.254669,0.012544,0.318628,17.254669,3909.963867,0.063726,0,,,,,,,,
19.560001,17.558064,0.012742,0.323654,17.558064,3978.713867,0.064731,0,,,,,,,,
19.92,17.985302,0.012975,0.329566,17.985302,4075.527344,0.065913,0,,,,,,,,
20.280001,18.456226,0.013238,0.336233,18.456226,4182.240234,0.067247,0,,,,,,,,
20.640001,18.899498,0.013474,0.342249,18.899498,4282.6875,0.06845,0,,,,,,,,
21.000002,19.213314,0.013692,0.34777,19.213314,4353.799316,0.069554,0,,,,,,,,
21.360001,19.668205,0.013943,0.35415,19.668205,4456.878906,0.07083,0,,,,,,,,
21.720001,20.075005,0.014182,0.360218,20.075005,4549.061035,0.072044,0,,,,,,,,
22.080002,20.473787,0.014418,0.366208,20.473787,4639.42627,0.073242,0,,,,,,,,
22.440001,20.911446,0.014665,0.372484,20.911446,4738.601074,0.074497,0,,,,,,,,
22.800001,21.200413,0.014878,0.377901,21.200413,4804.082031,0.07558,0,,,,,,,,
23.160002,21.65731,0.01512,0.384047,21.65731,4907.616211,0.076809,0,,,,,,,,
23.52,21.986757,0.015349,0.389854,21.986757,4982.27002,0.077971,0,,,,,,,,
23.880001,22.359489,0.015584,0.395844,22.359489,5066.732422,0.079169,0,,,,,,,,
24.240002,22.701761,0.015805,0.401443,22.701761,5144.29248,0.080289,0,,,,,,,,
24.6,23.06848,0.016051,0.407693,23.06848,5227.39209,0.081539,0,,,,,,,,
24.960001,23.52137,0.016303,0.4141,23.52137,5330.018066,0.08282,0,,,,,,,,
25.320002,23.876867,0.016548,0.420324,23.876867,5410.575684,0.084065,0,,,,,,,,
25.68,24.273245,0.016768,0.425897,24.273245,5500.395996,0.085179,0,,,,,,,,
26.040001,24.58666,0.017006,0.431965,24.58666,5571.416504,0.086393,0,,,,,,,,
26.400002,24.959793,0.017229,0.437616,24.959793,5655.969727,0.087523,0,,,,,,,,
26.760002,25.36619,0.017472,0.443788,25.36619,5748.060547,0.088758,0,,,,,,,,
27.120001,25.82509,0.017722,0.450142,25.82509,5852.049316,0.090028,0,,,,,,,,
27.480001,26.100031,0.017944,0.455767,26.100031,5914.351562,0.091153,0,,,,,,,,
27.840002,26.535686,0.018196,0.462174,26.535686,6013.072266,0.092435,0,,,,,,,,
28.200001,26.902004,0.01842,0.467877,26.902004,6096.081055,0.093575,0,,,,,,,,
28.560001,27.263916,0.018661,0.473997,27.263916,6178.091309,0.094799,0,,,,,,,,
28.920002,27.626627,0.018907,0.480247,27.626627,6260.282715,0.096049,0,,,,,,,,
29.280001,27.992546,0.019143,0.486237,27.992546,6343.20166,0.097247,0,,,,,,,,
29.640001,28.282314,0.019349,0.491471,28.282314,6408.86377,0.098294,0,,,,,,,,
30.000002,28.68791,0.019604,0.49793,28.68791,6500.772949,0.099586,0,,,,,,,,
30.360001,29.114748,0.019838,0.503894,29.114748,6597.496094,0.100779,0,,,,,,,,
30.720001,29.488281,0.020076,0.509935,29.488281,6682.139648,0.101987,0,,,,,,,,
31.080002,29.900692,0.02031,0.515873,29.900692,6775.59375,0.103175,0,,,,,,,,
31.440002,30.178436,0.020536,0.521602,30.178436,6838.53125,0.10432,0,,,,,,,,
31.800001,30.668198,0.020799,0.528295,30.668198,6949.512695,0.105659,0,,,,,,,,
32.16,30.927908,0.021022,0.533947,30.927908,7008.36377,0.106789,0,,,,,,,,
32.52,31.391216,0.021271,0.540275,31.391216,7113.351074,0.108055,0,,,,,,,,
32.880001,31.593615,0.021474,0.545431,31.593615,7159.215332,0.109086,0,,,,,,,,
33.240002,32.033276,0.021732,0.551994,32.033276,7258.84375,0.110399,0,,,,,,,,
33.600002,32.414825,0.021963,0.557853,32.414825,7345.304199,0.111571,0,,,,,,,,
33.960003,32.882145,0.022207,0.564052,32.882145,7451.200195,0.11281,0,,,,,,,,
34.320004,33.125019,0.022429,0.569703,33.125019,7506.236328,0.113941,0,,,,,,,,
34.68,33.523403,0.022681,0.576109,33.523403,7596.51123,0.115222,0,,,,,,,,
35.040001,33.927395,0.022917,0.582099,33.927395,7688.057617,0.11642,0,,,,,,,,
35.400002,34.2873,0.023157,0.588193,34.2873,7769.612793,0.117639,0,,,,,,,,
35.760002,34.544205,0.023377,0.593766,34.544205,7827.828125,0.118753,0,,,,,,,,
36.120003,34.795498,0.023592,0.599235,34.795498,7884.771973,0.119847,0,,,,,,,,
36.480003,35.272835,0.023843,0.605615,35.272835,7992.938477,0.121123,0,,,,,,,,
36.84,35.743359,0.024101,0.612178,35.743359,8099.560059,0.122436,0,,,,,,,,
37.200001,35.973011,0.024316,0.617621,35.973011,8151.600586,0.123524,0,,,,,,,,
37.560001,36.39143,0.024562,0.623871,36.39143,8246.416016,0.124774,0,,,,,,,,
37.920002,36.75174,0.024803,0.629991,36.75174,8328.0625,0.125998,0,,,,,,,,
38.280003,37.112045,0.025043,0.636085,37.112045,8409.708984,0.127217,0,,,,,,,,
38.640003,37.519646,0.025286,0.642257,37.519646,8502.073242,0.128451,0,,,,,,,,
39,37.667538,0.025494,0.647543,37.667538,8535.585937,0.129509,0,,,,,,,,
39.360001,38.077541,0.025745,0.653924,38.077541,8628.494141,0.130785,0,,,,,,,,
39.720001,38.40218,0.025973,0.659705,38.40218,8702.057617,0.131941,0,,,,,,,,
40.080002,38.839836,0.026219,0.665955,38.839836,8801.232422,0.133191,0,,,,,,,,
40.440002,39.077103,0.026439,0.671554,39.077103,8854.998047,0.134311,0,,,,,,,,
40.800003,39.387314,0.026671,0.67744,39.387314,8925.292969,0.135488,0,,,,,,,,
41.160004,39.901119,0.026933,0.684107,39.901119,9041.722656,0.136821,0,,,,,,,,
41.52,40.207321,0.027164,0.689966,40.207321,9111.108398,0.137993,0,,,,,,,,
41.880001,40.47665,0.027391,0.695722,40.47665,9172.139648,0.139144,0,,,,,,,,
42.240002,40.778843,0.02762,0.701555,40.778843,9240.618164,0.140311,0,,,,,,,,
42.600002,41.23053,0.027876,0.70804,41.23053,9342.97168,0.141608,0,,,,,,,,
42.960003,41.452164,0.028089,0.713457,41.452164,9393.194336,0.142691,0,,,,,,,,
43.320004,41.853752,0.028332,0.719629,41.853752,9484.195312,0.143926,0,,,,,,,,
43.68,42.120277,0.028557,0.725358,42.120277,9544.59082,0.145072,0,,,,,,,,
44.040001,42.574768,0.028811,0.73179,42.574768,9647.580078,0.146358,0,,,,,,,,
44.400002,42.896198,0.029051,0.737884,42.896198,9720.416992,0.147577,0,,,,,,,,
44.760002,43.303398,0.029296,0.744108,43.303398,9812.69043,0.148822,0,,,,,,,,
45.120003,43.55349,0.029524,0.749916,43.55349,9869.361328,0.149983,0,,,,,,,,
45.480003,43.774323,0.02974,0.755385,43.774323,9919.402344,0.151077,0,,,,,,,,
45.840004,44.38472,0.030007,0.762182,44.38472,10057.7207,0.152436,0,,,,,,,,
46.200001,44.558262,0.030228,0.767781,44.558262,10097.0459,0.153556,0,,,,,,,,
46.560001,44.811558,0.030453,0.77351,44.811558,10154.44336,0.154702,0,,,,,,,,
46.920002,45.193108,0.030694,0.77963,45.193108,10240.9043,0.155926,0,,,,,,,,
47.280003,45.564636,0.030932,0.785672,45.564636,10325.09375,0.157134,0,,,,,,,,
47.640003,45.971035,0.031182,0.792026,45.971035,10417.18555,0.158405,0,,,,,,,,
48.000004,46.28886,0.031421,0.798094,46.28886,10489.20508,0.159619,0,,,,,,,,
48.360001,46.475224,0.031632,0.803459,46.475224,10531.43555,0.160692,0,,,,,,,,
48.720001,46.932922,0.031884,0.809865,46.932922,10635.15234,0.161973,0,,,,,,,,
49.080002,47.223091,0.032112,0.815647,47.223091,10700.90527,0.163129,0,,,,,,,,
49.440002,47.597828,0.032353,0.821767,47.597828,10785.82129,0.164353,0,,,,,,,,
49.800003,47.770969,0.032574,0.827392,47.770969,10825.05566,0.165478,0,,,,,,,,
50.160004,48.166946,0.03281,0.833382,48.166946,10914.78613,0.166676,0,,,,,,,,
50.520004,48.612621,0.033071,0.839996,48.612621,11015.77734,0.167999,0,,,,,,,,
50.880001,48.802593,0.03329,0.845569,48.802593,11058.82617,0.169114,0,,,,,,,,
51.240002,49.254681,0.033552,0.85221,49.254681,11161.26953,0.170442,0,,,,,,,,
51.600002,49.278728,0.03374,0.857002,49.278728,11166.71973,0.1714,0,,,,,,,,
51.960003,49.65226,0.033987,0.863278,49.65226,11251.36328,0.172656,0,,,,,,,,
52.320004,50.168472,0.034239,0.869659,50.168472,11368.33789,0.173932,0,,,,,,,,
52.680004,50.473473,0.034483,0.875857,50.473473,11437.45215,0.175171,0,,,,,,,,
53.040001,50.639801,0.034692,0.881169,50.639801,11475.14258,0.176234,0,,,,,,,,
53.400002,51.068241,0.03495,0.887732,51.068241,11572.22754,0.177546,0,,,,,,,,
53.760002,51.439369,0.035188,0.893774,51.439369,11656.32715,0.178755,0,,,,,,,,
54.120003,51.662205,0.035424,0.899764,51.662205,11706.82227,0.179953,0,,,,,,,,
54.480003,52.038143,0.035669,0.905988,52.038143,11792.01172,0.181198,0,,,,,,,,
54.840004,52.219299,0.035878,0.9113,52.219299,11833.06152,0.18226,0,,,,,,,,
55.200001,52.592834,0.036127,0.917629,52.592834,11917.70606,0.183526,0,,,,,,,,
55.560001,52.841721,0.036358,0.923488,52.841721,11974.10449,0.184698,0,,,,,,,,
55.920002,53.157944,0.036587,0.929322,53.157944,12045.7627,0.185864,0,,,,,,,,
56.280003,53.366352,0.036818,0.935181,53.366352,12092.98828,0.187036,0,,,,,,,,
56.640003,53.782768,0.037072,0.94164,53.782768,12187.34863,0.188328,0,,,,,,,,
57.000004,54.104198,0.03731,0.947681,54.104198,12260.18555,0.189536,0,,,,,,,,
57.360004,54.504986,0.037566,0.954166,54.504986,12351.00586,0.190833,0,,,,,,,,
57.720001,54.52142,0.037773,0.959427,54.52142,12354.72949,0.191885,0,,,,,,,,
58.080002,54.923409,0.038028,0.965911,54.923409,12445.82129,0.193182,0,,,,,,,,
58.440002,55.145844,0.038237,0.971224,55.145844,12496.22656,0.194245,0,,,,,,,,
58.800003,55.461262,0.038484,0.9775,55.461262,12567.70117,0.1955,0,,,,,,,,
59.160004,55.82037,0.038724,0.983594,55.82037,12649.0752,0.196719,0,,,,,,,,
59.520004,56.058834,0.038955,0.989453,56.058834,12703.11328,0.197891,0,,,,,,,,
59.880001,56.456818,0.039201,0.995704,56.456818,12793.29688,0.199141,0,,,,,,,,
60.240002,56.601902,0.039421,1.001303,56.601902,12826.17383,0.200261,0,,,,,,,,
60.600002,56.91692,0.039674,1.007709,56.91692,12897.55762,0.201542,0,,,,,,,,
60.960003,57.222721,0.039912,1.013777,57.222721,12966.85352,0.202755,0,,,,,,,,
61.320004,57.571404,0.040152,1.019871,57.571404,13045.86621,0.203974,0,,,,,,,,
61.680004,57.589439,0.040354,1.025001,57.589439,13049.95313,0.205,0,,,,,,,,
62.040005,58.108059,0.040616,1.031642,58.108059,13167.47363,0.206328,0,,,,,,,,
62.400002,58.317268,0.040841,1.037371,58.317268,13214.88086,0.207474,0,,,,,,,,
62.760002,58.652328,0.041088,1.043648,58.652328,13290.80762,0.20873,0,,,,,,,,
63.120003,58.889591,0.04132,1.049533,58.889591,13344.57227,0.209907,0,,,,,,,,
63.480003,59.052311,0.041547,1.055289,59.052311,13381.44531,0.211058,0,,,,,,,,
63.840004,59.479149,0.041803,1.061799,59.479149,13478.16699,0.21236,0,,,,,,,,
64.200005,59.652691,0.042035,1.067685,59.652691,13517.49316,0.213537,0,,,,,,,,
64.560005,59.998569,0.042274,1.073753,59.998569,13595.86914,0.214751,0,,,,,,,,
64.920006,59.848274,0.042448,1.07818,59.848274,13561.81152,0.215636,0,,,,,,,,
65.280006,60.501556,0.042746,1.085758,60.501556,13709.84863,0.217152,0,,,,,,,,
65.639999,60.729603,0.042971,1.091461,60.729603,13761.52441,0.218292,0,,,,,,,,
66,61.066265,0.043206,1.097425,61.066265,13837.81348,0.219485,0,,,,,,,,
66.360001,61.237,0.043442,1.103415,61.237,13876.50195,0.220683,0,,,,,,,,
66.720001,61.636185,0.043697,1.109899,61.636185,13966.95801,0.22198,0,,,,,,,,
67.080002,61.829361,0.043924,1.115681,61.829361,14010.73242,0.223136,0,,,,,,,,
67.440002,62.049797,0.044161,1.121697,62.049797,14060.68457,0.224339,0,,,,,,,,
67.800003,62.225342,0.044388,1.127452,62.225342,14100.46387,0.22549,0,,,,,,,,
68.160004,62.379242,0.044608,1.133051,62.379242,14135.33691,0.22661,0,,,,,,,,
68.520004,62.709091,0.044847,1.139119,62.709091,14210.08203,0.227824,0,,,,,,,,
68.880005,63.156368,0.045108,1.145734,63.156368,14311.43652,0.229147,0,,,,,,,,
69.240005,63.210873,0.045322,1.151177,63.210873,14323.78809,0.230235,0,,,,,,,,
69.600006,63.600441,0.04557,1.157479,63.600441,14412.06543,0.231496,0,,,,,,,,
69.960007,63.878586,0.04581,1.163573,63.878586,14475.09375,0.232715,0,,,,,,,,
70.32,64.126274,0.046052,1.169719,64.126274,14531.2207,0.233944,0,,,,,,,,
70.68,64.369545,0.046292,1.175813,64.369545,14586.34668,0.235163,0,,,,,,,,
71.040001,64.484978,0.0465,1.181099,64.484978,14612.50488,0.23622,0,,,,,,,,
71.400002,64.956299,0.046757,1.187636,64.956299,14719.30664,0.237527,0,,,,,,,,
71.760002,65.041672,0.046979,1.193261,65.041672,14738.65234,0.238652,0,,,,,,,,
72.120003,65.348671,0.047224,1.199485,65.348671,14808.2207,0.239897,0,,,,,,,,
72.480003,65.506584,0.047442,1.205032,65.506584,14844.00391,0.241006,0,,,,,,,,
72.840004,65.654068,0.04768,1.211074,65.654068,14877.42383,0.242215,0,,,,,,,,
73.200005,66.175095,0.047948,1.217871,66.175095,14995.49023,0.243574,0,,,,,,,,
73.560005,66.369072,0.048176,1.223678,66.369072,15039.44629,0.244736,0,,,,,,,,
73.920006,66.507744,0.048406,1.229512,66.507744,15070.86914,0.245902,0,,,,,,,,
74.280006,66.761444,0.048637,1.235371,66.761444,15128.35938,0.247074,0,,,,,,,,
74.640007,67.208725,0.048888,1.241752,67.208725,15229.71484,0.24835,0,,,,,,,,
75,67.22876,0.049099,1.247117,67.22876,15234.25391,0.249423,0,,,,,,,,
75.360001,67.479652,0.049336,1.253132,67.479652,15291.10742,0.250626,0,,,,,,,,
75.720001,67.639969,0.049565,1.25894,67.639969,15327.43555,0.251788,0,,,,,,,,
76.080002,67.995468,0.049816,1.26532,67.995468,15407.99316,0.253064,0,,,,,,,,
76.440002,68.312889,0.050062,1.27157,68.312889,15479.92188,0.254314,0,,,,,,,,
76.800003,68.526512,0.05031,1.277873,68.526512,15528.3291,0.255575,0,,,,,,,,
77.160004,68.729706,0.050539,1.28368,68.729706,15574.37305,0.256736,0,,,,,,,,
77.520004,68.830704,0.050753,1.289123,68.830704,15597.25977,0.257825,0,,,,,,,,
77.880005,69.396614,0.051013,1.295738,69.396614,15725.49707,0.259148,0,,,,,,,,
78.240005,69.380989,0.05124,1.301493,69.380989,15721.95606,0.260299,0,,,,,,,,
78.600006,69.554527,0.051459,1.307066,69.554527,15761.28027,0.261413,0,,,,,,,,
78.960007,69.984573,0.051713,1.313499,69.984573,15858.73047,0.2627,0,,,,,,,,
79.320007,70.114021,0.051939,1.319254,70.114021,15888.06348,0.263851,0,,,,,,,,
79.68,70.32885,0.052185,1.325504,70.32885,15936.74512,0.265101,0,,,,,,,,
80.040001,70.683144,0.052436,1.331885,70.683144,16017.02832,0.266377,0,,,,,,,,
80.400002,70.524429,0.052632,1.336859,70.524429,15981.06348,0.267372,0,,,,,,,,
80.760002,71.058678,0.052893,1.343473,71.058678,16102.12598,0.268695,0,,,,,,,,
81.120003,71.245445,0.053121,1.349281,71.245445,16144.44824,0.269856,0,,,,,,,,
81.480003,71.592926,0.053359,1.355323,71.592926,16223.18848,0.271065,0,,,,,,,,
81.840004,71.607353,0.053581,1.360948,71.607353,16226.45703,0.27219,0,,,,,,,,
82.200005,71.905144,0.05381,1.366781,71.905144,16293.9375,0.273356,0,,,,,,,,
82.560005,72.310738,0.054082,1.373682,72.310738,16385.8457,0.274736,0,,,,,,,,
82.920006,72.344406,0.054301,1.379256,72.344406,16393.47656,0.275851,0,,,,,,,,
83.280006,72.667038,0.054556,1.385714,72.667038,16466.58594,0.277143,0,,,,,,,,
83.640007,72.465439,0.054739,1.390375,72.465439,16420.90234,0.278075,0,,,,,,,,
84.000008,72.945984,0.055006,1.397147,72.945984,16529.79492,0.279429,0,,,,,,,,
84.360001,73.275429,0.055245,1.403214,73.275429,16604.44922,0.280643,0,,,,,,,,
84.720001,73.559586,0.055493,1.409517,73.559586,16668.83984,0.281903,0,,,,,,,,
85.080002,73.555176,0.055702,1.414829,73.555176,16667.83984,0.282966,0,,,,,,,,
85.440002,74.01889,0.055963,1.42147,74.01889,16772.91992,0.284294,0,,,,,,,,
85.800003,74.184013,0.05619,1.427225,74.184013,16810.33789,0.285445,0,,,,,,,,
86.160004,74.357155,0.056436,1.433476,74.357155,16849.57227,0.286695,0,,,,,,,,
86.520004,74.64492,0.056684,1.439778,74.64492,16914.7793,0.287956,0,,,,,,,,
86.880005,74.70063,0.056893,1.445091,74.70063,16927.4043,0.289018,0,,,,,,,,
87.240005,74.991997,0.057128,1.451054,74.991997,16993.42773,0.290211,0,,,,,,,,
87.600006,75.075363,0.057351,1.456705,75.075363,17012.31836,0.291341,0,,,,,,,,
87.960007,75.48056,0.05761,1.463294,75.48056,17104.13867,0.292659,0,,,,,,,,
88.320007,75.619232,0.057835,1.468997,75.619232,17135.5625,0.2938,0,,,,,,,,
88.680008,75.885353,0.058078,1.47517,75.885353,17195.86719,0.295034,0,,,,,,,,
89.040001,76.040459,0.058312,1.481133,76.040459,17231.01367,0.296227,0,,,,,,,,
89.400002,76.460083,0.058579,1.487904,76.460083,17326.10352,0.297581,0,,,,,,,,
89.760002,76.327019,0.058788,1.493217,76.327019,17295.94922,0.298643,0,,,,,,,,
90.120003,76.737823,0.059044,1.499727,76.737823,17389.03906,0.299946,0,,,,,,,,
90.480003,76.740234,0.059243,1.50478,76.740234,17389.58398,0.300956,0,,,,,,,,
90.840004,77.134201,0.0595,1.51129,77.134201,17478.85742,0.302258,0,,,,,,,,
91.200005,77.369865,0.059734,1.517254,77.369865,17532.26172,0.303451,0,,,,,,,,
91.560005,77.776665,0.059974,1.523348,77.776665,17624.44336,0.30467,0,,,,,,,,
91.920006,78.143784,0.060208,1.529286,78.143784,17707.63477,0.305857,0,,,,,,,,
92.280006,78.346581,0.060431,1.534937,78.346581,17753.58789,0.306987,0,,,,,,,,
92.640007,78.868813,0.060689,1.541499,78.868813,17871.92969,0.3083,0,,,,,,,,
93.000008,79.060783,0.060922,1.547411,79.060783,17915.42773,0.309482,0,,,,,,,,
93.360008,79.393036,0.061155,1.553349,79.393036,17990.71875,0.31067,0,,,,,,,,
93.720001,79.38903,0.061367,1.558713,79.38903,17989.81055,0.311743,0,,,,,,,,
94.080002,79.95414,0.061625,1.565276,79.95414,18117.86719,0.313055,0,,,,,,,,
94.440002,80.134491,0.061859,1.571214,80.134491,18158.73438,0.314243,0,,,,,,,,
94.800003,80.481171,0.062095,1.577204,80.481171,18237.29297,0.315441,0,,,,,,,,
95.160004,80.737679,0.062339,1.583402,80.737679,18295.41992,0.31668,0,,,,,,,,
95.520004,80.798996,0.062564,1.589131,80.798996,18309.3125,0.317826,0,,,,,,,,
95.880005,81.193771,0.062811,1.595407,81.193771,18398.76953,0.319081,0,,,,,,,,
96.240005,81.394966,0.063049,1.601449,81.394966,18444.36133,0.32029,0,,,,,,,,
96.600006,81.629829,0.063276,1.607204,81.629829,18497.58203,0.321441,0,,,,,,,,
96.960007,81.637848,0.063489,1.612621,81.637848,18499.40039,0.322524,0,,,,,,,,
97.320007,82.267479,0.063753,1.619314,82.267479,18642.07617,0.323863,0,,,,,,,,
97.680008,82.399742,0.063988,1.625304,82.399742,18672.04688,0.325061,0,,,,,,,,
98.040001,82.65023,0.064215,1.631059,82.65023,18728.80859,0.326212,0,,,,,,,,
98.400002,82.857841,0.064453,1.637101,82.857841,18775.85547,0.32742,0,,,,,,,,
98.760002,83.34359,0.064706,1.643533,83.34359,18885.92773,0.328707,0,,,,,,,,
99.120003,83.47625,0.064936,1.649367,83.47625,18915.98828,0.329873,0,,,,,,,,
99.480003,83.695885,0.065175,1.655435,83.695885,18965.75781,0.331087,0,,,,,,,,
99.840004,83.854599,0.065392,1.660956,83.854599,19001.72266,0.332191,0,,,,,,,,
100.200005,84.069817,0.065628,1.666945,84.069817,19050.49219,0.333389,0,,,,,,,,
100.560005,84.281837,0.065852,1.672649,84.281837,19098.53711,0.33453,0,,,,,,,,
100.920006,84.794838,0.066109,1.679159,84.794838,19214.7832,0.335832,0,,,,,,,,
101.280006,84.882614,0.066331,1.684811,84.882614,19234.67578,0.336962,0,,,,,,,,
101.640007,85.2826,0.066573,1.690956,85.2826,19325.3125,0.338191,0,,,,,,,,
102.000008,85.52227,0.066815,1.697103,85.52227,19379.62305,0.339421,0,,,,,,,,
102.360008,85.812836,0.067061,1.703353,85.812836,19445.46484,0.340671,0,,,,,,,,
102.720001,86.081764,0.067304,1.709525,86.081764,19506.40625,0.341905,0,,,,,,,,
103.080002,86.052109,0.067505,1.714629,86.052109,19499.68555,0.342926,0,,,,,,,,
103.440002,86.658897,0.067773,1.721426,86.658897,19637.18555,0.344285,0,,,,,,,,
103.800003,86.715813,0.067989,1.726921,86.715813,19650.08398,0.345384,0,,,,,,,,
104.160004,87.004776,0.068228,1.732989,87.004776,19715.5625,0.346598,0,,,,,,,,
104.520004,87.182327,0.068458,1.738822,87.182327,19755.79688,0.347764,0,,,,,,,,
104.880005,87.290939,0.068683,1.744552,87.290939,19780.4082,0.34891,0,,,,,,,,
105.240005,88.01236,0.068961,1.751609,88.01236,19943.88477,0.350322,0,,,,,,,,
105.600006,88.162651,0.069191,1.757443,88.162651,19977.94141,0.351489,0,,,,,,,,
105.960007,88.228378,0.06941,1.763016,88.228378,19992.83594,0.352603,0,,,,,,,,
106.320007,88.590691,0.069649,1.769083,88.590691,20074.9375,0.353817,0,,,,,,,,
106.680008,89.046387,0.069893,1.775282,89.046387,20178.19922,0.355056,0,,,,,,,,
107.040009,89.039169,0.07011,1.780803,89.039169,20176.56445,0.356161,0,,,,,,,,
107.400002,89.340164,0.070343,1.786714,89.340164,20244.76953,0.357343,0,,,,,,,,
107.760002,89.510895,0.070578,1.792678,89.510895,20283.45703,0.358536,0,,,,,,,,
108.120003,89.936134,0.070829,1.799058,89.936134,20379.81836,0.359812,0,,,,,,,,
108.480003,90.257965,0.071062,1.80497,90.257965,20452.74609,0.360994,0,,,,,,,,
108.840004,90.625885,0.071319,1.811507,90.625885,20536.11914,0.362301,0,,,,,,,,
109.200005,90.718872,0.071539,1.81708,90.718872,20557.18945,0.363416,0,,,,,,,,
109.560005,90.844315,0.07176,1.822705,90.844315,20585.61328,0.364541,0,,,,,,,,
109.920006,91.464333,0.072018,1.829268,91.464333,20726.11328,0.365854,0,,,,,,,,
110.280006,91.644287,0.072255,1.835283,91.644287,20766.89063,0.367057,0,,,,,,,,
110.640007,91.635071,0.072466,1.840648,91.635071,20764.80273,0.36813,0,,,,,,,,
111.000008,92.220619,0.072722,1.847133,92.220619,20897.49023,0.369427,0,,,,,,,,
111.360008,92.297165,0.072949,1.852914,92.297165,20914.83594,0.370583,0,,,,,,,,
111.720009,92.586136,0.073189,1.859008,92.586136,20980.31836,0.371802,0,,,,,,,,
112.080002,93.053856,0.073445,1.865492,93.053856,21086.30273,0.373098,0,,,,,,,,
112.440002,93.08992,0.07366,1.870961,93.08992,21094.47656,0.374192,0,,,,,,,,
112.800003,93.520767,0.073903,1.877133,93.520767,21192.10742,0.375427,0,,,,,,,,
113.160004,93.634995,0.074125,1.882785,93.634995,21217.99219,0.376557,0,,,,,,,,
113.520004,94.027763,0.074366,1.888904,94.027763,21306.99609,0.377781,0,,,,,,,,
113.880005,94.253807,0.074595,1.894712,94.253807,21358.2168,0.378942,0,,,,,,,,
114.240005,94.49147,0.074831,1.900702,94.49147,21412.07227,0.38014,0,,,,,,,,
114.600006,95.093452,0.07509,1.90729,95.093452,21548.48438,0.381458,0,,,,,,,,
114.960007,95.176018,0.075315,1.912994,95.176018,21567.19336,0.382599,0,,,,,,,,
115.320007,95.606865,0.07556,1.919218,95.606865,21664.82422,0.383844,0,,,,,,,,
115.680008,95.128723,0.07575,1.924062,95.128723,21556.47656,0.384812,0,,,,,,,,
116.040009,95.881004,0.076013,1.930728,95.881004,21726.94531,0.386146,0,,,,,,,,
116.400009,96.143921,0.076252,1.936796,96.143921,21786.52344,0.387359,0,,,,,,,,
116.760002,96.568748,0.0765,1.943099,96.568748,21882.79102,0.38862,0,,,,,,,,
117.120003,96.657326,0.076726,1.948828,96.657326,21902.86328,0.389766,0,,,,,,,,
117.480003,97.19558,0.076976,1.955182,97.19558,22024.83203,0.391036,0,,,,,,,,
117.840004,97.357498,0.077203,1.960964,97.357498,22061.52344,0.392193,0,,,,,,,,
118.200005,97.741455,0.07745,1.96724,97.741455,22148.5293,0.393448,0,,,,,,,,
118.560005,98.003967,0.077689,1.973308,98.003967,22208.01563,0.394662,0,,,,,,,,
118.920006,97.989136,0.077907,1.978829,97.989136,22204.6543,0.395766,0,,,,,,,,
119.280006,98.369484,0.078132,1.984558,98.369484,22290.8418,0.396912,0,,,,,,,,
119.640007,98.630798,0.078375,1.99073,98.630798,22350.05664,0.398146,0,,,,,,,,
120.000008,99.051628,0.078621,1.99698,99.051628,22445.41992,0.399396,0,,,,,,,,
120.360008,99.13459,0.078842,2.002579,99.13459,22464.21875,0.400516,0,,,,,,,,
120.720009,99.624748,0.079089,2.008856,99.624748,22575.29102,0.401771,0,,,,,,,,
121.080009,99.81192,0.079316,2.014637,99.81192,22617.70313,0.402927,0,,,,,,,,
121.440002,100.442757,0.079586,2.021486,100.442757,22760.65234,0.404297,0,,,,,,,,
121.800003,100.474014,0.079805,2.027059,100.474014,22767.73633,0.405412,0,,,,,,,,
122.160004,100.960175,0.080057,2.033439,100.960175,22877.90039,0.406688,0,,,,,,,,
122.520004,100.779816,0.08025,2.038362,100.779816,22837.03125,0.407672,0,,,,,,,,
122.880005,101.354546,0.08051,2.04495,101.354546,22967.26758,0.40899,0,,,,,,,,
123.240005,101.630287,0.080742,2.050836,101.630287,23029.75195,0.410167,0,,,,,,,,
123.600006,102.016647,0.080991,2.057164,102.016647,23117.30078,0.411433,0,,,,,,,,
123.960007,102.170547,0.081211,2.062763,102.170547,23152.17773,0.412553,0,,,,,,,,
124.320007,102.382164,0.081448,2.068779,102.382164,23200.13086,0.413756,0,,,,,,,,
124.680008,102.815414,0.081703,2.075264,102.815414,23298.30469,0.415053,0,,,,,,,,
125.040009,102.947273,0.081927,2.080941,102.947273,23328.18359,0.416188,0,,,,,,,,
125.400009,103.25267,0.082154,2.086722,103.25267,23397.38867,0.417344,0,,,,,,,,
125.76001,103.392143,0.082371,2.092217,103.392143,23428.99414,0.418443,0,,,,,,,,
126.120003,103.897133,0.082631,2.098832,103.897133,23543.42578,0.419766,0,,,,,,,,
126.480003,104.25985,0.082867,2.104822,104.25985,23625.61914,0.420964,0,,,,,,,,
126.840004,104.528778,0.083099,2.110707,104.528778,23686.55859,0.422141,0,,,,,,,,
127.200005,104.923149,0.083344,2.116931,104.923149,23775.92578,0.423386,0,,,,,,,,
127.560005,104.981667,0.08358,2.122921,104.981667,23789.18555,0.424584,0,,,,,,,,
127.920006,105.428543,0.083818,2.128989,105.428543,23890.44922,0.425798,0,,,,,,,,
128.279999,105.669418,0.084061,2.135161,105.669418,23945.03125,0.427032,0,,,,,,,,
128.639999,105.774017,0.08428,2.140708,105.774017,23968.73438,0.428142,0,,,,,,,,
129,105.889046,0.084501,2.146333,105.889046,23994.80078,0.429267,0,,,,,,,,
129.360001,106.395241,0.084746,2.152557,106.395241,24109.50586,0.430511,0,,,,,,,,
129.720001,106.852539,0.085001,2.159016,106.852539,24213.13086,0.431803,0,,,,,,,,
130.080002,106.960747,0.085222,2.164641,106.960747,24237.65039,0.432928,0,,,,,,,,
130.440002,107.365143,0.085461,2.170709,107.365143,24329.28711,0.434142,0,,,,,,,,
130.800003,107.841278,0.08571,2.177037,107.841278,24437.18164,0.435407,0,,,,,,,,
131.160004,107.953499,0.085946,2.183027,107.953499,24462.61133,0.436605,0,,,,,,,,
131.520004,108.220825,0.086175,2.188834,108.220825,24523.1875,0.437767,0,,,,,,,,
131.880005,108.377129,0.086403,2.194642,108.377129,24558.60742,0.438928,0,,,,,,,,
132.240005,108.804367,0.086647,2.20084,108.804367,24655.41992,0.440168,0,,,,,,,,
132.600006,108.825211,0.086856,2.206153,108.825211,24660.14453,0.441231,0,,,,,,,,
132.960007,109.449234,0.087119,2.212819,109.449234,24801.55078,0.442564,0,,,,,,,,
133.320007,109.575081,0.087339,2.218419,109.575081,24830.06641,0.443684,0,,,,,,,,
133.680008,109.845215,0.087575,2.224408,109.845215,24891.2793,0.444882,0,,,,,,,,
134.040009,110.341385,0.08783,2.230893,110.341385,25003.71484,0.446179,0,,,,,,,,
134.400009,110.565025,0.08807,2.236987,110.565025,25054.39258,0.447397,0,,,,,,,,
134.76001,111.0103,0.088312,2.243133,111.0103,25155.29297,0.448627,0,,,,,,,,
135.12001,110.920921,0.088524,2.248497,110.920921,25135.03906,0.449699,0,,,,,,,,
135.480011,111.589432,0.088784,2.255112,111.589432,25286.52734,0.451022,0,,,,,,,,
135.840012,111.548553,0.089001,2.260633,111.548553,25277.26367,0.452127,0,,,,,,,,
136.200012,111.894432,0.089229,2.266415,111.894432,25355.64063,0.453283,0,,,,,,,,
136.560013,112.11647,0.089466,2.27243,112.11647,25405.95508,0.454486,0,,,,,,,,
136.920013,112.662338,0.089713,2.278707,112.662338,25529.65039,0.455741,0,,,,,,,,
137.280014,113.118034,0.089968,2.285191,113.118034,25632.91211,0.457038,0,,,,,,,,
137.639999,113.348892,0.090199,2.291051,113.348892,25685.22656,0.45821,0,,,,,,,,
138,113.319633,0.090416,2.296572,113.319633,25678.5957,0.459314,0,,,,,,,,
138.360001,113.746872,0.090658,2.302717,113.746872,25775.4082,0.460544,0,,,,,,,,
138.720001,114.122406,0.090894,2.308707,114.122406,25860.50586,0.461741,0,,,,,,,,
139.080002,114.29715,0.091124,2.314541,114.29715,25900.10352,0.462908,0,,,,,,,,
139.440002,114.499947,0.091351,2.320322,114.499947,25946.05859,0.464064,0,,,,,,,,
139.800003,114.843025,0.091588,2.326338,114.843025,26023.80078,0.465268,0,,,,,,,,
140.160004,115.274666,0.09184,2.332744,115.274666,26121.61133,0.466549,0,,,,,,,,
140.520004,115.539185,0.092071,2.338604,115.539185,26181.55273,0.467721,0,,,,,,,,
140.880005,116.112717,0.092326,2.345088,116.112717,26311.51758,0.469018,0,,,,,,,,
141.240005,116.103897,0.092539,2.350479,116.103897,26309.51758,0.470096,0,,,,,,,,
141.600006,116.261002,0.092761,2.356131,116.261002,26345.11719,0.471226,0,,,,,,,,
141.960007,116.970795,0.093025,2.362823,116.970795,26505.95898,0.472565,0,,,,,,,,
142.320007,117.194839,0.093255,2.368683,117.194839,26556.72852,0.473737,0,,,,,,,,
142.680008,117.295036,0.093478,2.374334,117.295036,26579.43555,0.474867,0,,,,,,,,
143.040009,117.848923,0.093724,2.380584,117.848923,26704.94727,0.476117,0,,,,,,,,
143.400009,117.787598,0.093939,2.386053,117.787598,26691.04883,0.477211,0,,,,,,,,
143.76001,118.468941,0.094205,2.392798,118.468941,26845.44336,0.47856,0,,,,,,,,
144.12001,118.87133,0.094453,2.3991,118.87133,26936.62891,0.47982,0,,,,,,,,
144.480011,118.991165,0.094671,2.404647,118.991165,26963.7832,0.480929,0,,,,,,,,
144.840012,119.388344,0.094914,2.41082,119.388344,27053.7832,0.482164,0,,,,,,,,
145.200012,119.512985,0.095127,2.416236,119.512985,27082.02734,0.483247,0,,,,,,,,
145.560013,119.91217,0.095372,2.42246,119.91217,27172.48633,0.484492,0,,,,,,,,
145.920013,120.122581,0.095594,2.428086,120.122581,27220.16602,0.485617,0,,,,,,,,
146.280014,120.683289,0.095853,2.434674,120.683289,27347.22266,0.486935,0,,,,,,,,
146.639999,121.039581,0.096094,2.440794,121.039581,27427.95898,0.488159,0,,,,,,,,
147,121.270439,0.096333,2.446862,121.270439,27480.27344,0.489372,0,,,,,,,,
147.360001,121.584656,0.096559,2.452591,121.584656,27551.47656,0.490518,0,,,,,,,,
147.720001,121.7117,0.096798,2.458659,121.7117,27580.26367,0.491732,0,,,,,,,,
148.080002,122.041954,0.097014,2.464154,122.041954,27655.10156,0.492831,0,,,,,,,,
148.440002,122.407867,0.097261,2.47043,122.407867,27738.01758,0.494086,0,,,,,,,,
148.800003,122.933701,0.097508,2.476707,122.933701,27857.17383,0.495341,0,,,,,,,,
149.160004,123.266754,0.09774,2.482592,123.266754,27932.64453,0.496518,0,,,,,,,,
149.520004,123.617447,0.097984,2.48879,123.617447,28012.11328,0.497758,0,,,,,,,,
149.880005,123.802605,0.098209,2.494519,123.802605,28054.07031,0.498904,0,,,,,,,,
150.240005,124.37854,0.09846,2.500874,124.37854,28184.58008,0.500175,0,,,,,,,,
150.600006,124.63504,0.098696,2.50689,124.63504,28242.70313,0.501378,0,,,,,,,,
150.960007,124.990135,0.098932,2.51288,124.990135,28323.16992,0.502576,0,,,,,,,,
151.320007,125.014984,0.099138,2.518114,125.014984,28328.80078,0.503623,0,,,,,,,,
151.680008,125.471481,0.099389,2.524468,125.471481,28432.24219,0.504894,0,,,,,,,,
152.040009,125.987694,0.099629,2.530588,125.987694,28549.2168,0.506118,0,,,,,,,,
152.400009,126.29911,0.099876,2.536839,126.29911,28619.78516,0.507368,0,,,,,,,,
152.76001,126.603302,0.100104,2.542646,126.603302,28688.7168,0.508529,0,,,,,,,,
153.12001,126.705505,0.100324,2.548219,126.705505,28711.87695,0.509644,0,,,,,,,,
153.480011,127.331932,0.100581,2.554756,127.331932,28853.82813,0.510951,0,,,,,,,,
153.840012,127.621704,0.100821,2.560849,127.621704,28919.49023,0.51217,0,,,,,,,,
154.200012,128.093033,0.101061,2.566943,128.093033,29026.29492,0.513389,0,,,,,,,,
154.560013,128.101044,0.101274,2.57236,128.101044,29028.10938,0.514472,0,,,,,,,,
154.920013,128.637695,0.101525,2.578741,128.637695,29149.7168,0.515748,0,,,,,,,,
155.280014,128.910629,0.10175,2.584444,128.910629,29211.56445,0.516889,0,,,,,,,,
155.640015,129.498581,0.101994,2.590642,129.498581,29344.79688,0.518128,0,,,,,,,,
156,129.545486,0.10222,2.596397,129.545486,29355.42578,0.519279,0,,,,,,,,
156.360001,129.796768,0.102458,2.602439,129.796768,29412.36719,0.520488,0,,,,,,,,
156.720001,130.565079,0.102715,2.60895,130.565079,29586.46875,0.52179,0,,,,,,,,
157.080002,130.585114,0.102936,2.614575,130.585114,29591.00781,0.522915,0,,,,,,,,
157.440002,130.878098,0.103169,2.620486,130.878098,29657.40039,0.524097,0,,,,,,,,
157.800003,131.104141,0.103388,2.62606,131.104141,29708.62109,0.525212,0,,,,,,,,
158.160004,131.764236,0.103635,2.632336,131.764236,29858.20117,0.526467,0,,,,,,,,
158.520004,132.211517,0.103885,2.63869,132.211517,29959.55859,0.527738,0,,,,,,,,
158.880005,132.448776,0.104106,2.644289,132.448776,30013.32031,0.528858,0,,,,,,,,
159.240005,133.054367,0.104362,2.6508,133.054367,30150.54883,0.53016,0,,,,,,,,
159.600006,133.433517,0.104599,2.656816,133.433517,30236.46484,0.531363,0,,,,,,,,
159.960007,133.56778,0.104832,2.662727,133.56778,30266.89063,0.532545,0,,,,,,,,
160.320007,134.100815,0.105076,2.668925,134.100815,30387.67969,0.533785,0,,,,,,,,
160.680008,134.03389,0.105286,2.674264,134.03389,30372.51172,0.534853,0,,,,,,,,
161.040009,134.405014,0.105517,2.680123,134.405014,30456.60938,0.536025,0,,,,,,,,
161.400009,135.054291,0.105771,2.686582,135.054291,30603.73828,0.537316,0,,,,,,,,
161.76001,135.523209,0.106007,2.692572,135.523209,30709.99609,0.538514,0,,,,,,,,
162.12001,135.786133,0.106235,2.698379,135.786133,30769.57617,0.539676,0,,,,,,,,
162.480011,136.078308,0.106468,2.704291,136.078308,30835.78516,0.540858,0,,,,,,,,
162.840012,136.812149,0.106728,2.71088,136.812149,31002.07422,0.542176,0,,,,,,,,
163.200012,137.103912,0.10696,2.716791,137.103912,31068.18945,0.543358,0,,,,,,,,
163.560013,137.22496,0.10718,2.722364,137.22496,31095.62109,0.544473,0,,,,,,,,
163.920013,137.648987,0.107422,2.72851,137.648987,31191.70508,0.545702,0,,,,,,,,
164.280014,138.121109,0.107666,2.734708,138.121109,31298.68945,0.546942,0,,,,,,,,
164.640015,138.063004,0.107867,2.739813,138.063004,31285.52344,0.547963,0,,,,,,,,
165.000015,138.878204,0.108127,2.746427,138.878204,31470.25,0.549286,0,,,,,,,,
165.360001,139.034103,0.108344,2.751948,139.034103,31505.57617,0.55039,0,,,,,,,,
165.720001,139.545105,0.108596,2.758329,139.545105,31621.37305,0.551666,0,,,,,,,,
166.080002,140.236465,0.108852,2.764839,140.236465,31778.03516,0.552968,0,,,,,,,,
166.440002,140.567917,0.10909,2.770881,140.567917,31853.14258,0.554176,0,,,,,,,,
166.800003,140.922211,0.109329,2.776949,140.922211,31933.42969,0.55539,0,,,,,,,,
167.160004,141.034027,0.10954,2.782314,141.034027,31958.76563,0.556463,0,,,,,,,,
167.520004,141.915359,0.109801,2.788954,141.915359,32158.47852,0.557791,0,,,,,,,,
167.880005,141.958649,0.110023,2.79458,141.958649,32168.28906,0.558916,0,,,,,,,,
168.240005,142.207138,0.110242,2.800153,142.207138,32224.59766,0.560031,0,,,,,,,,
168.600006,142.752197,0.110493,2.806533,142.752197,32348.10938,0.561307,0,,,,,,,,
168.960007,143.30809,0.110726,2.812445,143.30809,32474.07617,0.562489,0,,,,,,,,
169.320007,143.835937,0.11097,2.818643,143.835937,32593.6875,0.563729,0,,,,,,,,
169.680008,144.247131,0.111217,2.824919,144.247131,32686.86523,0.564984,0,,,,,,,,
170.040009,144.305649,0.111427,2.830258,144.305649,32700.125,0.566052,0,,,,,,,,
170.400009,144.732086,0.111664,2.836273,144.732086,32796.75781,0.567255,0,,,,,,,,
170.76001,145.387772,0.111902,2.842315,145.387772,32945.33984,0.568463,0,,,,,,,,
171.12001,145.878738,0.112147,2.84854,145.878738,33056.59375,0.569708,0,,,,,,,,
171.480011,146.097168,0.112368,2.854139,146.097168,33106.08984,0.570828,0,,,,,,,,
171.840012,146.59935,0.112607,2.860206,146.59935,33219.88672,0.572041,0,,,,,,,,
172.200012,147.167664,0.112856,2.866535,147.167664,33348.66797,0.573307,0,,,,,,,,
172.560013,147.414963,0.113073,2.872056,147.414963,33404.70703,0.574411,0,,,,,,,,
172.920013,148.158417,0.11334,2.878827,148.158417,33573.17578,0.575765,0,,,,,,,,
173.280014,148.334763,0.113556,2.884322,148.334763,33613.13672,0.576864,0,,,,,,,,
173.640015,148.432953,0.113771,2.889791,148.432953,33635.38672,0.577958,0,,,,,,,,
174.000015,149.34996,0.114031,2.896379,149.34996,33843.18359,0.579276,0,,,,,,,,
174.360016,149.829697,0.114271,2.902473,149.829697,33951.89453,0.580495,0,,,,,,,,
174.720001,149.997223,0.114489,2.90802,149.997223,33989.85547,0.581604,0,,,,,,,,
175.080002,150.657318,0.114743,2.914479,150.657318,34139.4375,0.582896,0,,,,,,,,
175.440002,151.113815,0.114975,2.920364,151.113815,34242.875,0.584073,0,,,,,,,,
175.800003,151.541855,0.11521,2.926328,151.541855,34339.875,0.585266,0,,,,,,,,
176.160004,152.144638,0.115464,2.932786,152.144638,34476.46484,0.586557,0,,,,,,,,
176.520004,152.22319,0.115671,2.938047,152.22319,34494.26563,0.587609,0,,,,,,,,
176.880005,152.95343,0.115918,2.944323,152.95343,34659.73828,0.588865,0,,,,,,,,
177.240005,153.114944,0.116134,2.949792,153.114944,34696.33984,0.589958,0,,,,,,,,
177.600006,153.853592,0.11639,2.956303,153.853592,34863.71875,0.591261,0,,,,,,,,
177.960007,154.223526,0.116616,2.962058,154.223526,34947.55078,0.592412,0,,,,,,,,
178.320007,154.887619,0.116865,2.96836,154.887619,35098.03516,0.593672,0,,,,,,,,
178.680008,155.343323,0.117099,2.974324,155.343323,35201.30078,0.594865,0,,,,,,,,
179.040009,156.012238,0.117356,2.980835,156.012238,35352.875,0.596167,0,,,,,,,,
179.400009,156.015839,0.11756,2.986017,156.015839,35353.69531,0.597203,0,,,,,,,,
179.76001,156.567719,0.117807,2.992293,156.567719,35478.75,0.598459,0,,,,,,,,
180.12001,156.988953,0.118033,2.998049,156.988953,35574.20313,0.59961,0,,,,,,,,
180.480011,157.549652,0.118265,3.003934,157.549652,35701.25781,0.600787,0,,,,,,,,
180.840012,158.311142,0.118515,3.010288,158.311142,35873.81641,0.602058,0,,,,,,,,
181.200012,158.763626,0.11875,3.016252,158.763626,35976.35156,0.60325,0,,,,,,,,
181.560013,159.32193,0.118989,3.02232,159.32193,36102.86328,0.604464,0,,,,,,,,
181.920013,159.749969,0.119215,3.028049,159.749969,36199.85938,0.60561,0,,,,,,,,
182.280014,160.370789,0.119469,3.034508,160.370789,36340.53516,0.606902,0,,,,,,,,
182.640015,160.794815,0.1197,3.040367,160.794815,36436.625,0.608074,0,,,,,,,,
183.000015,161.339081,0.11994,3.046487,161.339081,36559.95703,0.609298,0,,,,,,,,
183.360016,161.356323,0.120141,3.051592,161.356323,36563.86328,0.610318,0,,,,,,,,
183.720001,162.339844,0.120409,3.058389,162.339844,36786.73047,0.611678,0,,,,,,,,
184.080002,162.769501,0.120634,3.064092,162.769501,36884.09375,0.612818,0,,,,,,,,
184.440002,163.520569,0.120881,3.070368,163.520569,37054.28906,0.614074,0,,,,,,,,
184.800003,163.945404,0.121116,3.076358,163.945404,37150.55859,0.615272,0,,,,,,,,
185.160004,164.179871,0.121335,3.081905,164.179871,37203.6875,0.616381,0,,,,,,,,
185.520004,165.108078,0.121591,3.088416,165.108078,37414.02344,0.617683,0,,,,,,,,
185.880005,165.706055,0.12183,3.094484,165.706055,37549.52734,0.618897,0,,,,,,,,
186.240005,166.24913,0.122065,3.100447,166.24913,37672.58984,0.620089,0,,,,,,,,
186.600006,165.920074,0.122238,3.104848,165.920074,37598.02344,0.62097,0,,,,,,,,
186.960007,167.379745,0.12254,3.112505,167.379745,37928.78906,0.622501,0,,,,,,,,
187.320007,167.701981,0.122761,3.11813,167.701981,38001.8125,0.623626,0,,,,,,,,
187.680008,168.349655,0.123,3.124198,168.349655,38148.57813,0.62484,0,,,,,,,,
188.040009,168.770477,0.123232,3.130084,168.770477,38243.93359,0.626017,0,,,,,,,,
188.400009,169.667038,0.123482,3.136438,169.667038,38447.10156,0.627288,0,,,,,,,,
188.76001,170.230545,0.123717,3.142401,170.230545,38574.79297,0.62848,0,,,,,,,,
189.12001,170.433731,0.12395,3.148339,170.433731,38620.83203,0.629668,0,,,,,,,,
189.480011,171.106659,0.124179,3.154146,171.106659,38773.32031,0.630829,0,,,,,,,,
189.840012,171.402435,0.1244,3.159772,171.402435,38840.34375,0.631954,0,,,,,,,,
190.200012,172.198807,0.124635,3.165735,172.198807,39020.80859,0.633147,0,,,,,,,,
190.560013,173.031631,0.124892,3.172246,173.031631,39209.52734,0.634449,0,,,,,,,,
190.920013,173.40477,0.125114,3.177897,173.40477,39294.08203,0.635579,0,,,,,,,,
191.280014,174.278091,0.125361,3.184173,174.278091,39491.98047,0.636835,0,,,,,,,,
191.640015,174.873657,0.125602,3.190293,174.873657,39626.93359,0.638059,0,,,,,,,,
192.000015,175.352188,0.125836,3.196231,175.352188,39735.375,0.639246,0,,,,,,,,
192.360016,176.121704,0.12608,3.202429,176.121704,39909.74609,0.640486,0,,,,,,,,
192.720016,176.30246,0.12629,3.207768,176.30246,39950.70703,0.641554,0,,,,,,,,
193.080002,177.168961,0.126535,3.213992,177.168961,40147.05859,0.642798,0,,,,,,,,
193.440002,177.968933,0.126771,3.219981,177.968933,40328.33594,0.643996,0,,,,,,,,
193.800003,178.693558,0.127007,3.225971,178.693558,40492.53516,0.645194,0,,,,,,,,
194.160004,179.283112,0.127237,3.231831,179.283112,40626.12891,0.646366,0,,,,,,,,
194.520004,179.716766,0.127461,3.237508,179.716766,40724.39844,0.647502,0,,,,,,,,
194.880005,180.876633,0.127731,3.244357,180.876633,40987.22656,0.648871,0,,,,,,,,
195.240005,181.534332,0.127967,3.250373,181.534332,41136.26563,0.650075,0,,,,,,,,
195.600006,181.882614,0.128178,3.255712,181.882614,41215.1875,0.651142,0,,,,,,,,
195.960007,182.877365,0.128428,3.262066,182.877365,41440.60156,0.652413,0,,,,,,,,
196.320007,183.710602,0.128669,3.268186,183.710602,41629.41406,0.653637,0,,,,,,,,
196.680008,183.948669,0.128875,3.273421,183.948669,41683.36328,0.654684,0,,,,,,,,
197.040009,184.992722,0.129129,3.279879,184.992722,41919.94922,0.655976,0,,,,,,,,
197.400009,185.481277,0.129346,3.2854,185.481277,42030.65625,0.65708,0,,,,,,,,
197.76001,186.3125,0.129594,3.291676,186.3125,42219.01172,0.658335,0,,,,,,,,
198.12001,187.465164,0.129853,3.298265,187.465164,42480.21094,0.659653,0,,,,,,,,
198.480011,188.182983,0.130087,3.304203,188.182983,42642.875,0.660841,0,,,,,,,,
198.840012,189.013412,0.130332,3.310427,189.013412,42831.05078,0.662085,0,,,,,,,,
199.200012,189.357681,0.130541,3.315739,189.357681,42909.0625,0.663148,0,,,,,,,,
199.560013,190.645004,0.1308,3.322328,190.645004,43200.77344,0.664466,0,,,,,,,,
199.920013,190.797714,0.131011,3.327667,190.797714,43235.375,0.665533,0,,,,,,,,
200.280014,191.5047,0.131239,3.333474,191.5047,43395.58203,0.666695,0,,,,,,,,
200.640015,192.715881,0.131496,3.340011,192.715881,43670.04297,0.668002,0,,,,,,,,
201.000015,193.448517,0.131725,3.345818,193.448517,43836.05859,0.669164,0,,,,,,,,
201.360016,194.382339,0.131969,3.352016,194.382339,44047.66797,0.670403,0,,,,,,,,
201.720016,195.267685,0.132217,3.358319,195.267685,44248.28906,0.671664,0,,,,,,,,
202.080017,195.634399,0.132428,3.363683,195.634399,44331.38672,0.672737,0,,,,,,,,
202.440002,196.362228,0.13266,3.369569,196.362228,44496.3125,0.673914,0,,,,,,,,
202.800003,197.453171,0.132901,3.375689,197.453171,44743.52734,0.675138,0,,,,,,,,
203.160004,198.445923,0.133147,3.381939,198.445923,44968.48438,0.676388,0,,,,,,,,
203.520004,199.055527,0.133375,3.387721,199.055527,45106.625,0.677544,0,,,,,,,,
203.880005,199.885956,0.133609,3.393658,199.885956,45294.80469,0.678732,0,,,,,,,,
204.240005,200.787323,0.133855,3.399908,200.787323,45499.05469,0.679982,0,,,,,,,,
204.600006,201.421768,0.134078,3.405586,201.421768,45642.82422,0.681117,0,,,,,,,,
204.960007,202.474228,0.134338,3.412174,202.474228,45881.3125,0.682435,0,,,,,,,,
205.320007,203.007675,0.134554,3.417669,203.007675,46002.19531,0.683534,0,,,,,,,,
205.680008,203.463776,0.134761,3.42293,203.463776,46105.55078,0.684586,0,,,,,,,,
206.040009,204.944672,0.135027,3.429675,204.944672,46441.125,0.685935,0,,,,,,,,
206.400009,205.693344,0.135265,3.435742,205.693344,46610.77734,0.687149,0,,,,,,,,
206.76001,206.382294,0.135487,3.441368,206.382294,46766.89453,0.688274,0,,,,,,,,
207.12001,207.30011,0.13573,3.44754,207.30011,46974.875,0.689508,0,,,,,,,,
207.480011,207.948578,0.13596,3.453373,207.948578,47121.82031,0.690675,0,,,,,,,,
207.840012,209.086807,0.136204,3.459571,209.086807,47379.74609,0.691914,0,,,,,,,,
208.200012,210.147293,0.136457,3.466004,210.147293,47620.05469,0.693201,0,,,,,,,,
208.560013,213.150391,0.136663,3.471238,213.150391,48300.56641,0.694248,0,,,,,,,,
208.920013,211.586121,0.136914,3.477618,211.586121,47946.09766,0.695524,0,,,,,,,,
209.280014,212.358032,0.137123,3.482931,212.358032,48121.01563,0.696586,0,,,,,,,,
209.640015,213.360001,0.137372,3.48926,213.360001,48348.06641,0.697852,0,,,,,,,,
210.000015,214.239319,0.137613,3.49538,214.239319,48547.32422,0.699076,0,,,,,,,,
210.360016,215.339081,0.137856,3.501552,215.339081,48796.53125,0.70031,0,,,,,,,,
210.720016,216.305374,0.138097,3.507671,216.305374,49015.49609,0.701534,0,,,,,,,,
211.080017,217.367462,0.138342,3.513896,217.367462,49256.16797,0.702779,0,,,,,,,,
211.440002,218.210312,0.138577,3.51986,218.210312,49447.16406,0.703972,0,,,,,,,,
211.800003,218.769409,0.138799,3.525485,218.769409,49573.85156,0.705097,0,,,,,,,,
212.160004,219.701248,0.139031,3.531396,219.701248,49785.01172,0.706279,0,,,,,,,,
212.520004,220.476364,0.139259,3.537178,220.476364,49960.65625,0.707436,0,,,,,,,,
212.880005,221.730835,0.13951,3.543558,221.730835,50244.92188,0.708712,0,,,,,,,,
213.240005,222.653442,0.139748,3.5496,222.653442,50453.98828,0.70992,0,,,,,,,,
213.600006,223.512329,0.13998,3.555485,223.512329,50648.61328,0.711097,0,,,,,,,,
213.960007,224.552765,0.140212,3.561397,224.552765,50884.38281,0.712279,0,,,,,,,,
214.320007,225.607635,0.14046,3.567673,225.607635,51123.41797,0.713535,0,,,,,,,,
214.680008,226.590775,0.140695,3.573663,226.590775,51346.20313,0.714733,0,,,,,,,,
215.040009,226.822418,0.140906,3.579001,226.822418,51398.69141,0.7158,0,,,,,,,,
215.400009,228.050827,0.141136,3.584861,228.050827,51677.05469,0.716972,0,,,,,,,,
215.76001,229.498077,0.141398,3.591502,229.498077,52005.00391,0.7183,0,,,,,,,,
216.12001,230.407852,0.141622,3.597205,230.407852,52211.16406,0.719441,0,,,,,,,,
216.480011,231.436279,0.141871,3.603533,231.436279,52444.21094,0.720707,0,,,,,,,,
216.840012,232.509583,0.142109,3.609575,232.509583,52687.42188,0.721915,0,,,,,,,,
217.200012,233.146835,0.14232,3.61494,233.146835,52831.82422,0.722988,0,,,,,,,,
217.560013,234.620132,0.142581,3.621555,234.620132,53165.68359,0.724311,0,,,,,,,,
217.920013,235.616089,0.142822,3.627675,235.616089,53391.36719,0.725535,0,,,,,,,,
218.280014,236.663742,0.143058,3.633665,236.663742,53628.76563,0.726733,0,,,,,,,,
218.640015,236.851715,0.143235,3.63817,236.851715,53671.36328,0.727634,0,,,,,,,,
219.000015,238.667679,0.143529,3.645644,238.667679,54082.86328,0.729129,0,,,,,,,,
219.360016,239.435577,0.143742,3.651035,239.435577,54256.875,0.730207,0,,,,,,,,
219.720016,240.835922,0.14399,3.657337,240.835922,54574.19922,0.731467,0,,,,,,,,
220.080017,241.669159,0.144211,3.662962,241.669159,54763.01563,0.732592,0,,,,,,,,
220.440018,243.196167,0.144473,3.669603,243.196167,55109.03906,0.733921,0,,,,,,,,
220.800003,244.381683,0.14471,3.675645,244.381683,55377.67969,0.735129,0,,,,,,,,
221.160004,245.126343,0.144935,3.681348,245.126343,55546.42188,0.73627,0,,,,,,,,
221.520004,246.417679,0.145172,3.687364,246.417679,55839.04297,0.737473,0,,,,,,,,
221.880005,247.089401,0.145388,3.692859,247.089401,55991.25781,0.738572,0,,,,,,,,
222.240005,248.53183,0.145629,3.698979,248.53183,56318.11719,0.739796,0,,,,,,,,
222.600006,249.634399,0.145876,3.705255,249.634399,56567.96094,0.741051,0,,,,,,,,
222.700012,250.098511,0.145932,3.706661,250.098511,56673.12891,0.741332,0,,,,,,,,